Internal Server Error: /bus/
Traceback (most recent call last):
  File "/Users/alfred.fan/git/new/cmdb/env/lib/python3.6/site-packages/django/db/backends/utils.py", line 85, in _execute
    return self.cursor.execute(sql, params)
  File "/Users/alfred.fan/git/new/cmdb/env/lib/python3.6/site-packages/django/db/backends/sqlite3/base.py", line 296, in execute
    return Database.Cursor.execute(self, query, params)
sqlite3.OperationalError: no such table: cmdb_bu

The above exception was the direct cause of the following exception:

Traceback (most recent call last):
  File "/Users/alfred.fan/git/new/cmdb/env/lib/python3.6/site-packages/django/core/handlers/exception.py", line 34, in inner
    response = get_response(request)
  File "/Users/alfred.fan/git/new/cmdb/env/lib/python3.6/site-packages/django/core/handlers/base.py", line 126, in _get_response
    response = self.process_exception_by_middleware(e, request)
  File "/Users/alfred.fan/git/new/cmdb/env/lib/python3.6/site-packages/django/core/handlers/base.py", line 124, in _get_response
    response = wrapped_callback(request, *callback_args, **callback_kwargs)
  File "/Users/alfred.fan/git/new/cmdb/env/lib/python3.6/site-packages/django/views/decorators/csrf.py", line 54, in wrapped_view
    return view_func(*args, **kwargs)
  File "/Users/alfred.fan/git/new/cmdb/env/lib/python3.6/site-packages/rest_framework/viewsets.py", line 103, in view
    return self.dispatch(request, *args, **kwargs)
  File "/Users/alfred.fan/git/new/cmdb/env/lib/python3.6/site-packages/rest_framework/views.py", line 483, in dispatch
    response = self.handle_exception(exc)
  File "/Users/alfred.fan/git/new/cmdb/env/lib/python3.6/site-packages/rest_framework/views.py", line 443, in handle_exception
    self.raise_uncaught_exception(exc)
  File "/Users/alfred.fan/git/new/cmdb/env/lib/python3.6/site-packages/rest_framework/views.py", line 480, in dispatch
    response = handler(request, *args, **kwargs)
  File "/Users/alfred.fan/git/new/cmdb/env/lib/python3.6/site-packages/rest_framework/mixins.py", line 20, in create
    serializer.is_valid(raise_exception=True)
  File "/Users/alfred.fan/git/new/cmdb/env/lib/python3.6/site-packages/rest_framework/serializers.py", line 236, in is_valid
    self._validated_data = self.run_validation(self.initial_data)
  File "/Users/alfred.fan/git/new/cmdb/env/lib/python3.6/site-packages/rest_framework/serializers.py", line 434, in run_validation
    value = self.to_internal_value(data)
  File "/Users/alfred.fan/git/new/cmdb/env/lib/python3.6/site-packages/rest_framework/serializers.py", line 488, in to_internal_value
    validated_value = field.run_validation(primitive_value)
  File "/Users/alfred.fan/git/new/cmdb/env/lib/python3.6/site-packages/rest_framework/fields.py", line 776, in run_validation
    return super(CharField, self).run_validation(data)
  File "/Users/alfred.fan/git/new/cmdb/env/lib/python3.6/site-packages/rest_framework/fields.py", line 524, in run_validation
    self.run_validators(value)
  File "/Users/alfred.fan/git/new/cmdb/env/lib/python3.6/site-packages/rest_framework/fields.py", line 538, in run_validators
    validator(value)
  File "/Users/alfred.fan/git/new/cmdb/env/lib/python3.6/site-packages/rest_framework/validators.py", line 81, in __call__
    if qs_exists(queryset):
  File "/Users/alfred.fan/git/new/cmdb/env/lib/python3.6/site-packages/rest_framework/validators.py", line 24, in qs_exists
    return queryset.exists()
  File "/Users/alfred.fan/git/new/cmdb/env/lib/python3.6/site-packages/django/db/models/query.py", line 718, in exists
    return self.query.has_results(using=self.db)
  File "/Users/alfred.fan/git/new/cmdb/env/lib/python3.6/site-packages/django/db/models/sql/query.py", line 516, in has_results
    return compiler.has_results()
  File "/Users/alfred.fan/git/new/cmdb/env/lib/python3.6/site-packages/django/db/models/sql/compiler.py", line 1035, in has_results
    return bool(self.execute_sql(SINGLE))
  File "/Users/alfred.fan/git/new/cmdb/env/lib/python3.6/site-packages/django/db/models/sql/compiler.py", line 1065, in execute_sql
    cursor.execute(sql, params)
  File "/Users/alfred.fan/git/new/cmdb/env/lib/python3.6/site-packages/django/db/backends/utils.py", line 100, in execute
    return super().execute(sql, params)
  File "/Users/alfred.fan/git/new/cmdb/env/lib/python3.6/site-packages/django/db/backends/utils.py", line 68, in execute
    return self._execute_with_wrappers(sql, params, many=False, executor=self._execute)
  File "/Users/alfred.fan/git/new/cmdb/env/lib/python3.6/site-packages/django/db/backends/utils.py", line 77, in _execute_with_wrappers
    return executor(sql, params, many, context)
  File "/Users/alfred.fan/git/new/cmdb/env/lib/python3.6/site-packages/django/db/backends/utils.py", line 85, in _execute
    return self.cursor.execute(sql, params)
  File "/Users/alfred.fan/git/new/cmdb/env/lib/python3.6/site-packages/django/db/utils.py", line 89, in __exit__
    raise dj_exc_value.with_traceback(traceback) from exc_value
  File "/Users/alfred.fan/git/new/cmdb/env/lib/python3.6/site-packages/django/db/backends/utils.py", line 85, in _execute
    return self.cursor.execute(sql, params)
  File "/Users/alfred.fan/git/new/cmdb/env/lib/python3.6/site-packages/django/db/backends/sqlite3/base.py", line 296, in execute
    return Database.Cursor.execute(self, query, params)
django.db.utils.OperationalError: no such table: cmdb_bu
[03/Oct/2018 07:34:56] "POST /bus/ HTTP/1.1" 500 17678
Internal Server Error: /bus/
Traceback (most recent call last):
  File "/Users/alfred.fan/git/new/cmdb/env/lib/python3.6/site-packages/django/db/backends/utils.py", line 85, in _execute
    return self.cursor.execute(sql, params)
  File "/Users/alfred.fan/git/new/cmdb/env/lib/python3.6/site-packages/django/db/backends/sqlite3/base.py", line 296, in execute
    return Database.Cursor.execute(self, query, params)
sqlite3.OperationalError: no such table: cmdb_bu

The above exception was the direct cause of the following exception:

Traceback (most recent call last):
  File "/Users/alfred.fan/git/new/cmdb/env/lib/python3.6/site-packages/django/core/handlers/exception.py", line 34, in inner
    response = get_response(request)
  File "/Users/alfred.fan/git/new/cmdb/env/lib/python3.6/site-packages/django/core/handlers/base.py", line 126, in _get_response
    response = self.process_exception_by_middleware(e, request)
  File "/Users/alfred.fan/git/new/cmdb/env/lib/python3.6/site-packages/django/core/handlers/base.py", line 124, in _get_response
    response = wrapped_callback(request, *callback_args, **callback_kwargs)
  File "/Users/alfred.fan/git/new/cmdb/env/lib/python3.6/site-packages/django/views/decorators/csrf.py", line 54, in wrapped_view
    return view_func(*args, **kwargs)
  File "/Users/alfred.fan/git/new/cmdb/env/lib/python3.6/site-packages/rest_framework/viewsets.py", line 103, in view
    return self.dispatch(request, *args, **kwargs)
  File "/Users/alfred.fan/git/new/cmdb/env/lib/python3.6/site-packages/rest_framework/views.py", line 483, in dispatch
    response = self.handle_exception(exc)
  File "/Users/alfred.fan/git/new/cmdb/env/lib/python3.6/site-packages/rest_framework/views.py", line 443, in handle_exception
    self.raise_uncaught_exception(exc)
  File "/Users/alfred.fan/git/new/cmdb/env/lib/python3.6/site-packages/rest_framework/views.py", line 480, in dispatch
    response = handler(request, *args, **kwargs)
  File "/Users/alfred.fan/git/new/cmdb/env/lib/python3.6/site-packages/rest_framework/mixins.py", line 20, in create
    serializer.is_valid(raise_exception=True)
  File "/Users/alfred.fan/git/new/cmdb/env/lib/python3.6/site-packages/rest_framework/serializers.py", line 236, in is_valid
    self._validated_data = self.run_validation(self.initial_data)
  File "/Users/alfred.fan/git/new/cmdb/env/lib/python3.6/site-packages/rest_framework/serializers.py", line 434, in run_validation
    value = self.to_internal_value(data)
  File "/Users/alfred.fan/git/new/cmdb/env/lib/python3.6/site-packages/rest_framework/serializers.py", line 488, in to_internal_value
    validated_value = field.run_validation(primitive_value)
  File "/Users/alfred.fan/git/new/cmdb/env/lib/python3.6/site-packages/rest_framework/fields.py", line 776, in run_validation
    return super(CharField, self).run_validation(data)
  File "/Users/alfred.fan/git/new/cmdb/env/lib/python3.6/site-packages/rest_framework/fields.py", line 524, in run_validation
    self.run_validators(value)
  File "/Users/alfred.fan/git/new/cmdb/env/lib/python3.6/site-packages/rest_framework/fields.py", line 538, in run_validators
    validator(value)
  File "/Users/alfred.fan/git/new/cmdb/env/lib/python3.6/site-packages/rest_framework/validators.py", line 81, in __call__
    if qs_exists(queryset):
  File "/Users/alfred.fan/git/new/cmdb/env/lib/python3.6/site-packages/rest_framework/validators.py", line 24, in qs_exists
    return queryset.exists()
  File "/Users/alfred.fan/git/new/cmdb/env/lib/python3.6/site-packages/django/db/models/query.py", line 718, in exists
    return self.query.has_results(using=self.db)
  File "/Users/alfred.fan/git/new/cmdb/env/lib/python3.6/site-packages/django/db/models/sql/query.py", line 516, in has_results
    return compiler.has_results()
  File "/Users/alfred.fan/git/new/cmdb/env/lib/python3.6/site-packages/django/db/models/sql/compiler.py", line 1035, in has_results
    return bool(self.execute_sql(SINGLE))
  File "/Users/alfred.fan/git/new/cmdb/env/lib/python3.6/site-packages/django/db/models/sql/compiler.py", line 1065, in execute_sql
    cursor.execute(sql, params)
  File "/Users/alfred.fan/git/new/cmdb/env/lib/python3.6/site-packages/django/db/backends/utils.py", line 100, in execute
    return super().execute(sql, params)
  File "/Users/alfred.fan/git/new/cmdb/env/lib/python3.6/site-packages/django/db/backends/utils.py", line 68, in execute
    return self._execute_with_wrappers(sql, params, many=False, executor=self._execute)
  File "/Users/alfred.fan/git/new/cmdb/env/lib/python3.6/site-packages/django/db/backends/utils.py", line 77, in _execute_with_wrappers
    return executor(sql, params, many, context)
  File "/Users/alfred.fan/git/new/cmdb/env/lib/python3.6/site-packages/django/db/backends/utils.py", line 85, in _execute
    return self.cursor.execute(sql, params)
  File "/Users/alfred.fan/git/new/cmdb/env/lib/python3.6/site-packages/django/db/utils.py", line 89, in __exit__
    raise dj_exc_value.with_traceback(traceback) from exc_value
  File "/Users/alfred.fan/git/new/cmdb/env/lib/python3.6/site-packages/django/db/backends/utils.py", line 85, in _execute
    return self.cursor.execute(sql, params)
  File "/Users/alfred.fan/git/new/cmdb/env/lib/python3.6/site-packages/django/db/backends/sqlite3/base.py", line 296, in execute
    return Database.Cursor.execute(self, query, params)
django.db.utils.OperationalError: no such table: cmdb_bu
[03/Oct/2018 07:34:56] "POST /bus/ HTTP/1.1" 500 17678
Internal Server Error: /bus/
Traceback (most recent call last):
  File "/Users/alfred.fan/git/new/cmdb/env/lib/python3.6/site-packages/django/db/backends/utils.py", line 85, in _execute
    return self.cursor.execute(sql, params)
  File "/Users/alfred.fan/git/new/cmdb/env/lib/python3.6/site-packages/django/db/backends/sqlite3/base.py", line 296, in execute
    return Database.Cursor.execute(self, query, params)
sqlite3.OperationalError: no such table: cmdb_bu

The above exception was the direct cause of the following exception:

Traceback (most recent call last):
  File "/Users/alfred.fan/git/new/cmdb/env/lib/python3.6/site-packages/django/core/handlers/exception.py", line 34, in inner
    response = get_response(request)
  File "/Users/alfred.fan/git/new/cmdb/env/lib/python3.6/site-packages/django/core/handlers/base.py", line 126, in _get_response
    response = self.process_exception_by_middleware(e, request)
  File "/Users/alfred.fan/git/new/cmdb/env/lib/python3.6/site-packages/django/core/handlers/base.py", line 124, in _get_response
    response = wrapped_callback(request, *callback_args, **callback_kwargs)
  File "/Users/alfred.fan/git/new/cmdb/env/lib/python3.6/site-packages/django/views/decorators/csrf.py", line 54, in wrapped_view
    return view_func(*args, **kwargs)
  File "/Users/alfred.fan/git/new/cmdb/env/lib/python3.6/site-packages/rest_framework/viewsets.py", line 103, in view
    return self.dispatch(request, *args, **kwargs)
  File "/Users/alfred.fan/git/new/cmdb/env/lib/python3.6/site-packages/rest_framework/views.py", line 483, in dispatch
    response = self.handle_exception(exc)
  File "/Users/alfred.fan/git/new/cmdb/env/lib/python3.6/site-packages/rest_framework/views.py", line 443, in handle_exception
    self.raise_uncaught_exception(exc)
  File "/Users/alfred.fan/git/new/cmdb/env/lib/python3.6/site-packages/rest_framework/views.py", line 480, in dispatch
    response = handler(request, *args, **kwargs)
  File "/Users/alfred.fan/git/new/cmdb/env/lib/python3.6/site-packages/rest_framework/mixins.py", line 20, in create
    serializer.is_valid(raise_exception=True)
  File "/Users/alfred.fan/git/new/cmdb/env/lib/python3.6/site-packages/rest_framework/serializers.py", line 236, in is_valid
    self._validated_data = self.run_validation(self.initial_data)
  File "/Users/alfred.fan/git/new/cmdb/env/lib/python3.6/site-packages/rest_framework/serializers.py", line 434, in run_validation
    value = self.to_internal_value(data)
  File "/Users/alfred.fan/git/new/cmdb/env/lib/python3.6/site-packages/rest_framework/serializers.py", line 488, in to_internal_value
    validated_value = field.run_validation(primitive_value)
  File "/Users/alfred.fan/git/new/cmdb/env/lib/python3.6/site-packages/rest_framework/fields.py", line 776, in run_validation
    return super(CharField, self).run_validation(data)
  File "/Users/alfred.fan/git/new/cmdb/env/lib/python3.6/site-packages/rest_framework/fields.py", line 524, in run_validation
    self.run_validators(value)
  File "/Users/alfred.fan/git/new/cmdb/env/lib/python3.6/site-packages/rest_framework/fields.py", line 538, in run_validators
    validator(value)
  File "/Users/alfred.fan/git/new/cmdb/env/lib/python3.6/site-packages/rest_framework/validators.py", line 81, in __call__
    if qs_exists(queryset):
  File "/Users/alfred.fan/git/new/cmdb/env/lib/python3.6/site-packages/rest_framework/validators.py", line 24, in qs_exists
    return queryset.exists()
  File "/Users/alfred.fan/git/new/cmdb/env/lib/python3.6/site-packages/django/db/models/query.py", line 718, in exists
    return self.query.has_results(using=self.db)
  File "/Users/alfred.fan/git/new/cmdb/env/lib/python3.6/site-packages/django/db/models/sql/query.py", line 516, in has_results
    return compiler.has_results()
  File "/Users/alfred.fan/git/new/cmdb/env/lib/python3.6/site-packages/django/db/models/sql/compiler.py", line 1035, in has_results
    return bool(self.execute_sql(SINGLE))
  File "/Users/alfred.fan/git/new/cmdb/env/lib/python3.6/site-packages/django/db/models/sql/compiler.py", line 1065, in execute_sql
    cursor.execute(sql, params)
  File "/Users/alfred.fan/git/new/cmdb/env/lib/python3.6/site-packages/django/db/backends/utils.py", line 100, in execute
    return super().execute(sql, params)
  File "/Users/alfred.fan/git/new/cmdb/env/lib/python3.6/site-packages/django/db/backends/utils.py", line 68, in execute
    return self._execute_with_wrappers(sql, params, many=False, executor=self._execute)
  File "/Users/alfred.fan/git/new/cmdb/env/lib/python3.6/site-packages/django/db/backends/utils.py", line 77, in _execute_with_wrappers
    return executor(sql, params, many, context)
  File "/Users/alfred.fan/git/new/cmdb/env/lib/python3.6/site-packages/django/db/backends/utils.py", line 85, in _execute
    return self.cursor.execute(sql, params)
  File "/Users/alfred.fan/git/new/cmdb/env/lib/python3.6/site-packages/django/db/utils.py", line 89, in __exit__
    raise dj_exc_value.with_traceback(traceback) from exc_value
  File "/Users/alfred.fan/git/new/cmdb/env/lib/python3.6/site-packages/django/db/backends/utils.py", line 85, in _execute
    return self.cursor.execute(sql, params)
  File "/Users/alfred.fan/git/new/cmdb/env/lib/python3.6/site-packages/django/db/backends/sqlite3/base.py", line 296, in execute
    return Database.Cursor.execute(self, query, params)
django.db.utils.OperationalError: no such table: cmdb_bu
[03/Oct/2018 07:34:56] "POST /bus/ HTTP/1.1" 500 17678
Internal Server Error: /products/
Traceback (most recent call last):
  File "/Users/alfred.fan/git/new/cmdb/env/lib/python3.6/site-packages/django/db/backends/utils.py", line 85, in _execute
    return self.cursor.execute(sql, params)
  File "/Users/alfred.fan/git/new/cmdb/env/lib/python3.6/site-packages/django/db/backends/sqlite3/base.py", line 296, in execute
    return Database.Cursor.execute(self, query, params)
sqlite3.OperationalError: no such table: cmdb_product

The above exception was the direct cause of the following exception:

Traceback (most recent call last):
  File "/Users/alfred.fan/git/new/cmdb/env/lib/python3.6/site-packages/django/core/handlers/exception.py", line 34, in inner
    response = get_response(request)
  File "/Users/alfred.fan/git/new/cmdb/env/lib/python3.6/site-packages/django/core/handlers/base.py", line 126, in _get_response
    response = self.process_exception_by_middleware(e, request)
  File "/Users/alfred.fan/git/new/cmdb/env/lib/python3.6/site-packages/django/core/handlers/base.py", line 124, in _get_response
    response = wrapped_callback(request, *callback_args, **callback_kwargs)
  File "/Users/alfred.fan/git/new/cmdb/env/lib/python3.6/site-packages/django/views/decorators/csrf.py", line 54, in wrapped_view
    return view_func(*args, **kwargs)
  File "/Users/alfred.fan/git/new/cmdb/env/lib/python3.6/site-packages/rest_framework/viewsets.py", line 103, in view
    return self.dispatch(request, *args, **kwargs)
  File "/Users/alfred.fan/git/new/cmdb/env/lib/python3.6/site-packages/rest_framework/views.py", line 483, in dispatch
    response = self.handle_exception(exc)
  File "/Users/alfred.fan/git/new/cmdb/env/lib/python3.6/site-packages/rest_framework/views.py", line 443, in handle_exception
    self.raise_uncaught_exception(exc)
  File "/Users/alfred.fan/git/new/cmdb/env/lib/python3.6/site-packages/rest_framework/views.py", line 480, in dispatch
    response = handler(request, *args, **kwargs)
  File "/Users/alfred.fan/git/new/cmdb/env/lib/python3.6/site-packages/rest_framework/mixins.py", line 20, in create
    serializer.is_valid(raise_exception=True)
  File "/Users/alfred.fan/git/new/cmdb/env/lib/python3.6/site-packages/rest_framework/serializers.py", line 236, in is_valid
    self._validated_data = self.run_validation(self.initial_data)
  File "/Users/alfred.fan/git/new/cmdb/env/lib/python3.6/site-packages/rest_framework/serializers.py", line 434, in run_validation
    value = self.to_internal_value(data)
  File "/Users/alfred.fan/git/new/cmdb/env/lib/python3.6/site-packages/rest_framework/serializers.py", line 488, in to_internal_value
    validated_value = field.run_validation(primitive_value)
  File "/Users/alfred.fan/git/new/cmdb/env/lib/python3.6/site-packages/rest_framework/fields.py", line 776, in run_validation
    return super(CharField, self).run_validation(data)
  File "/Users/alfred.fan/git/new/cmdb/env/lib/python3.6/site-packages/rest_framework/fields.py", line 524, in run_validation
    self.run_validators(value)
  File "/Users/alfred.fan/git/new/cmdb/env/lib/python3.6/site-packages/rest_framework/fields.py", line 538, in run_validators
    validator(value)
  File "/Users/alfred.fan/git/new/cmdb/env/lib/python3.6/site-packages/rest_framework/validators.py", line 81, in __call__
    if qs_exists(queryset):
  File "/Users/alfred.fan/git/new/cmdb/env/lib/python3.6/site-packages/rest_framework/validators.py", line 24, in qs_exists
    return queryset.exists()
  File "/Users/alfred.fan/git/new/cmdb/env/lib/python3.6/site-packages/django/db/models/query.py", line 718, in exists
    return self.query.has_results(using=self.db)
  File "/Users/alfred.fan/git/new/cmdb/env/lib/python3.6/site-packages/django/db/models/sql/query.py", line 516, in has_results
    return compiler.has_results()
  File "/Users/alfred.fan/git/new/cmdb/env/lib/python3.6/site-packages/django/db/models/sql/compiler.py", line 1035, in has_results
    return bool(self.execute_sql(SINGLE))
  File "/Users/alfred.fan/git/new/cmdb/env/lib/python3.6/site-packages/django/db/models/sql/compiler.py", line 1065, in execute_sql
    cursor.execute(sql, params)
  File "/Users/alfred.fan/git/new/cmdb/env/lib/python3.6/site-packages/django/db/backends/utils.py", line 100, in execute
    return super().execute(sql, params)
  File "/Users/alfred.fan/git/new/cmdb/env/lib/python3.6/site-packages/django/db/backends/utils.py", line 68, in execute
    return self._execute_with_wrappers(sql, params, many=False, executor=self._execute)
  File "/Users/alfred.fan/git/new/cmdb/env/lib/python3.6/site-packages/django/db/backends/utils.py", line 77, in _execute_with_wrappers
    return executor(sql, params, many, context)
  File "/Users/alfred.fan/git/new/cmdb/env/lib/python3.6/site-packages/django/db/backends/utils.py", line 85, in _execute
    return self.cursor.execute(sql, params)
  File "/Users/alfred.fan/git/new/cmdb/env/lib/python3.6/site-packages/django/db/utils.py", line 89, in __exit__
    raise dj_exc_value.with_traceback(traceback) from exc_value
  File "/Users/alfred.fan/git/new/cmdb/env/lib/python3.6/site-packages/django/db/backends/utils.py", line 85, in _execute
    return self.cursor.execute(sql, params)
  File "/Users/alfred.fan/git/new/cmdb/env/lib/python3.6/site-packages/django/db/backends/sqlite3/base.py", line 296, in execute
    return Database.Cursor.execute(self, query, params)
django.db.utils.OperationalError: no such table: cmdb_product
[03/Oct/2018 07:34:57] "POST /products/ HTTP/1.1" 500 17713
Internal Server Error: /products/
Traceback (most recent call last):
  File "/Users/alfred.fan/git/new/cmdb/env/lib/python3.6/site-packages/django/db/backends/utils.py", line 85, in _execute
    return self.cursor.execute(sql, params)
  File "/Users/alfred.fan/git/new/cmdb/env/lib/python3.6/site-packages/django/db/backends/sqlite3/base.py", line 296, in execute
    return Database.Cursor.execute(self, query, params)
sqlite3.OperationalError: no such table: cmdb_product

The above exception was the direct cause of the following exception:

Traceback (most recent call last):
  File "/Users/alfred.fan/git/new/cmdb/env/lib/python3.6/site-packages/django/core/handlers/exception.py", line 34, in inner
    response = get_response(request)
  File "/Users/alfred.fan/git/new/cmdb/env/lib/python3.6/site-packages/django/core/handlers/base.py", line 126, in _get_response
    response = self.process_exception_by_middleware(e, request)
  File "/Users/alfred.fan/git/new/cmdb/env/lib/python3.6/site-packages/django/core/handlers/base.py", line 124, in _get_response
    response = wrapped_callback(request, *callback_args, **callback_kwargs)
  File "/Users/alfred.fan/git/new/cmdb/env/lib/python3.6/site-packages/django/views/decorators/csrf.py", line 54, in wrapped_view
    return view_func(*args, **kwargs)
  File "/Users/alfred.fan/git/new/cmdb/env/lib/python3.6/site-packages/rest_framework/viewsets.py", line 103, in view
    return self.dispatch(request, *args, **kwargs)
  File "/Users/alfred.fan/git/new/cmdb/env/lib/python3.6/site-packages/rest_framework/views.py", line 483, in dispatch
    response = self.handle_exception(exc)
  File "/Users/alfred.fan/git/new/cmdb/env/lib/python3.6/site-packages/rest_framework/views.py", line 443, in handle_exception
    self.raise_uncaught_exception(exc)
  File "/Users/alfred.fan/git/new/cmdb/env/lib/python3.6/site-packages/rest_framework/views.py", line 480, in dispatch
    response = handler(request, *args, **kwargs)
  File "/Users/alfred.fan/git/new/cmdb/env/lib/python3.6/site-packages/rest_framework/mixins.py", line 20, in create
    serializer.is_valid(raise_exception=True)
  File "/Users/alfred.fan/git/new/cmdb/env/lib/python3.6/site-packages/rest_framework/serializers.py", line 236, in is_valid
    self._validated_data = self.run_validation(self.initial_data)
  File "/Users/alfred.fan/git/new/cmdb/env/lib/python3.6/site-packages/rest_framework/serializers.py", line 434, in run_validation
    value = self.to_internal_value(data)
  File "/Users/alfred.fan/git/new/cmdb/env/lib/python3.6/site-packages/rest_framework/serializers.py", line 488, in to_internal_value
    validated_value = field.run_validation(primitive_value)
  File "/Users/alfred.fan/git/new/cmdb/env/lib/python3.6/site-packages/rest_framework/fields.py", line 776, in run_validation
    return super(CharField, self).run_validation(data)
  File "/Users/alfred.fan/git/new/cmdb/env/lib/python3.6/site-packages/rest_framework/fields.py", line 524, in run_validation
    self.run_validators(value)
  File "/Users/alfred.fan/git/new/cmdb/env/lib/python3.6/site-packages/rest_framework/fields.py", line 538, in run_validators
    validator(value)
  File "/Users/alfred.fan/git/new/cmdb/env/lib/python3.6/site-packages/rest_framework/validators.py", line 81, in __call__
    if qs_exists(queryset):
  File "/Users/alfred.fan/git/new/cmdb/env/lib/python3.6/site-packages/rest_framework/validators.py", line 24, in qs_exists
    return queryset.exists()
  File "/Users/alfred.fan/git/new/cmdb/env/lib/python3.6/site-packages/django/db/models/query.py", line 718, in exists
    return self.query.has_results(using=self.db)
  File "/Users/alfred.fan/git/new/cmdb/env/lib/python3.6/site-packages/django/db/models/sql/query.py", line 516, in has_results
    return compiler.has_results()
  File "/Users/alfred.fan/git/new/cmdb/env/lib/python3.6/site-packages/django/db/models/sql/compiler.py", line 1035, in has_results
    return bool(self.execute_sql(SINGLE))
  File "/Users/alfred.fan/git/new/cmdb/env/lib/python3.6/site-packages/django/db/models/sql/compiler.py", line 1065, in execute_sql
    cursor.execute(sql, params)
  File "/Users/alfred.fan/git/new/cmdb/env/lib/python3.6/site-packages/django/db/backends/utils.py", line 100, in execute
    return super().execute(sql, params)
  File "/Users/alfred.fan/git/new/cmdb/env/lib/python3.6/site-packages/django/db/backends/utils.py", line 68, in execute
    return self._execute_with_wrappers(sql, params, many=False, executor=self._execute)
  File "/Users/alfred.fan/git/new/cmdb/env/lib/python3.6/site-packages/django/db/backends/utils.py", line 77, in _execute_with_wrappers
    return executor(sql, params, many, context)
  File "/Users/alfred.fan/git/new/cmdb/env/lib/python3.6/site-packages/django/db/backends/utils.py", line 85, in _execute
    return self.cursor.execute(sql, params)
  File "/Users/alfred.fan/git/new/cmdb/env/lib/python3.6/site-packages/django/db/utils.py", line 89, in __exit__
    raise dj_exc_value.with_traceback(traceback) from exc_value
  File "/Users/alfred.fan/git/new/cmdb/env/lib/python3.6/site-packages/django/db/backends/utils.py", line 85, in _execute
    return self.cursor.execute(sql, params)
  File "/Users/alfred.fan/git/new/cmdb/env/lib/python3.6/site-packages/django/db/backends/sqlite3/base.py", line 296, in execute
    return Database.Cursor.execute(self, query, params)
django.db.utils.OperationalError: no such table: cmdb_product
[03/Oct/2018 07:34:57] "POST /products/ HTTP/1.1" 500 17713
Internal Server Error: /products/
Traceback (most recent call last):
  File "/Users/alfred.fan/git/new/cmdb/env/lib/python3.6/site-packages/django/db/backends/utils.py", line 85, in _execute
    return self.cursor.execute(sql, params)
  File "/Users/alfred.fan/git/new/cmdb/env/lib/python3.6/site-packages/django/db/backends/sqlite3/base.py", line 296, in execute
    return Database.Cursor.execute(self, query, params)
sqlite3.OperationalError: no such table: cmdb_product

The above exception was the direct cause of the following exception:

Traceback (most recent call last):
  File "/Users/alfred.fan/git/new/cmdb/env/lib/python3.6/site-packages/django/core/handlers/exception.py", line 34, in inner
    response = get_response(request)
  File "/Users/alfred.fan/git/new/cmdb/env/lib/python3.6/site-packages/django/core/handlers/base.py", line 126, in _get_response
    response = self.process_exception_by_middleware(e, request)
  File "/Users/alfred.fan/git/new/cmdb/env/lib/python3.6/site-packages/django/core/handlers/base.py", line 124, in _get_response
    response = wrapped_callback(request, *callback_args, **callback_kwargs)
  File "/Users/alfred.fan/git/new/cmdb/env/lib/python3.6/site-packages/django/views/decorators/csrf.py", line 54, in wrapped_view
    return view_func(*args, **kwargs)
  File "/Users/alfred.fan/git/new/cmdb/env/lib/python3.6/site-packages/rest_framework/viewsets.py", line 103, in view
    return self.dispatch(request, *args, **kwargs)
  File "/Users/alfred.fan/git/new/cmdb/env/lib/python3.6/site-packages/rest_framework/views.py", line 483, in dispatch
    response = self.handle_exception(exc)
  File "/Users/alfred.fan/git/new/cmdb/env/lib/python3.6/site-packages/rest_framework/views.py", line 443, in handle_exception
    self.raise_uncaught_exception(exc)
  File "/Users/alfred.fan/git/new/cmdb/env/lib/python3.6/site-packages/rest_framework/views.py", line 480, in dispatch
    response = handler(request, *args, **kwargs)
  File "/Users/alfred.fan/git/new/cmdb/env/lib/python3.6/site-packages/rest_framework/mixins.py", line 20, in create
    serializer.is_valid(raise_exception=True)
  File "/Users/alfred.fan/git/new/cmdb/env/lib/python3.6/site-packages/rest_framework/serializers.py", line 236, in is_valid
    self._validated_data = self.run_validation(self.initial_data)
  File "/Users/alfred.fan/git/new/cmdb/env/lib/python3.6/site-packages/rest_framework/serializers.py", line 434, in run_validation
    value = self.to_internal_value(data)
  File "/Users/alfred.fan/git/new/cmdb/env/lib/python3.6/site-packages/rest_framework/serializers.py", line 488, in to_internal_value
    validated_value = field.run_validation(primitive_value)
  File "/Users/alfred.fan/git/new/cmdb/env/lib/python3.6/site-packages/rest_framework/fields.py", line 776, in run_validation
    return super(CharField, self).run_validation(data)
  File "/Users/alfred.fan/git/new/cmdb/env/lib/python3.6/site-packages/rest_framework/fields.py", line 524, in run_validation
    self.run_validators(value)
  File "/Users/alfred.fan/git/new/cmdb/env/lib/python3.6/site-packages/rest_framework/fields.py", line 538, in run_validators
    validator(value)
  File "/Users/alfred.fan/git/new/cmdb/env/lib/python3.6/site-packages/rest_framework/validators.py", line 81, in __call__
    if qs_exists(queryset):
  File "/Users/alfred.fan/git/new/cmdb/env/lib/python3.6/site-packages/rest_framework/validators.py", line 24, in qs_exists
    return queryset.exists()
  File "/Users/alfred.fan/git/new/cmdb/env/lib/python3.6/site-packages/django/db/models/query.py", line 718, in exists
    return self.query.has_results(using=self.db)
  File "/Users/alfred.fan/git/new/cmdb/env/lib/python3.6/site-packages/django/db/models/sql/query.py", line 516, in has_results
    return compiler.has_results()
  File "/Users/alfred.fan/git/new/cmdb/env/lib/python3.6/site-packages/django/db/models/sql/compiler.py", line 1035, in has_results
    return bool(self.execute_sql(SINGLE))
  File "/Users/alfred.fan/git/new/cmdb/env/lib/python3.6/site-packages/django/db/models/sql/compiler.py", line 1065, in execute_sql
    cursor.execute(sql, params)
  File "/Users/alfred.fan/git/new/cmdb/env/lib/python3.6/site-packages/django/db/backends/utils.py", line 100, in execute
    return super().execute(sql, params)
  File "/Users/alfred.fan/git/new/cmdb/env/lib/python3.6/site-packages/django/db/backends/utils.py", line 68, in execute
    return self._execute_with_wrappers(sql, params, many=False, executor=self._execute)
  File "/Users/alfred.fan/git/new/cmdb/env/lib/python3.6/site-packages/django/db/backends/utils.py", line 77, in _execute_with_wrappers
    return executor(sql, params, many, context)
  File "/Users/alfred.fan/git/new/cmdb/env/lib/python3.6/site-packages/django/db/backends/utils.py", line 85, in _execute
    return self.cursor.execute(sql, params)
  File "/Users/alfred.fan/git/new/cmdb/env/lib/python3.6/site-packages/django/db/utils.py", line 89, in __exit__
    raise dj_exc_value.with_traceback(traceback) from exc_value
  File "/Users/alfred.fan/git/new/cmdb/env/lib/python3.6/site-packages/django/db/backends/utils.py", line 85, in _execute
    return self.cursor.execute(sql, params)
  File "/Users/alfred.fan/git/new/cmdb/env/lib/python3.6/site-packages/django/db/backends/sqlite3/base.py", line 296, in execute
    return Database.Cursor.execute(self, query, params)
django.db.utils.OperationalError: no such table: cmdb_product
[03/Oct/2018 07:34:57] "POST /products/ HTTP/1.1" 500 17713
Internal Server Error: /applications/
Traceback (most recent call last):
  File "/Users/alfred.fan/git/new/cmdb/env/lib/python3.6/site-packages/django/db/backends/utils.py", line 85, in _execute
    return self.cursor.execute(sql, params)
  File "/Users/alfred.fan/git/new/cmdb/env/lib/python3.6/site-packages/django/db/backends/sqlite3/base.py", line 296, in execute
    return Database.Cursor.execute(self, query, params)
sqlite3.OperationalError: no such table: cmdb_application

The above exception was the direct cause of the following exception:

Traceback (most recent call last):
  File "/Users/alfred.fan/git/new/cmdb/env/lib/python3.6/site-packages/django/core/handlers/exception.py", line 34, in inner
    response = get_response(request)
  File "/Users/alfred.fan/git/new/cmdb/env/lib/python3.6/site-packages/django/core/handlers/base.py", line 126, in _get_response
    response = self.process_exception_by_middleware(e, request)
  File "/Users/alfred.fan/git/new/cmdb/env/lib/python3.6/site-packages/django/core/handlers/base.py", line 124, in _get_response
    response = wrapped_callback(request, *callback_args, **callback_kwargs)
  File "/Users/alfred.fan/git/new/cmdb/env/lib/python3.6/site-packages/django/views/decorators/csrf.py", line 54, in wrapped_view
    return view_func(*args, **kwargs)
  File "/Users/alfred.fan/git/new/cmdb/env/lib/python3.6/site-packages/rest_framework/viewsets.py", line 103, in view
    return self.dispatch(request, *args, **kwargs)
  File "/Users/alfred.fan/git/new/cmdb/env/lib/python3.6/site-packages/rest_framework/views.py", line 483, in dispatch
    response = self.handle_exception(exc)
  File "/Users/alfred.fan/git/new/cmdb/env/lib/python3.6/site-packages/rest_framework/views.py", line 443, in handle_exception
    self.raise_uncaught_exception(exc)
  File "/Users/alfred.fan/git/new/cmdb/env/lib/python3.6/site-packages/rest_framework/views.py", line 480, in dispatch
    response = handler(request, *args, **kwargs)
  File "/Users/alfred.fan/git/new/cmdb/env/lib/python3.6/site-packages/rest_framework/mixins.py", line 20, in create
    serializer.is_valid(raise_exception=True)
  File "/Users/alfred.fan/git/new/cmdb/env/lib/python3.6/site-packages/rest_framework/serializers.py", line 236, in is_valid
    self._validated_data = self.run_validation(self.initial_data)
  File "/Users/alfred.fan/git/new/cmdb/env/lib/python3.6/site-packages/rest_framework/serializers.py", line 434, in run_validation
    value = self.to_internal_value(data)
  File "/Users/alfred.fan/git/new/cmdb/env/lib/python3.6/site-packages/rest_framework/serializers.py", line 488, in to_internal_value
    validated_value = field.run_validation(primitive_value)
  File "/Users/alfred.fan/git/new/cmdb/env/lib/python3.6/site-packages/rest_framework/fields.py", line 776, in run_validation
    return super(CharField, self).run_validation(data)
  File "/Users/alfred.fan/git/new/cmdb/env/lib/python3.6/site-packages/rest_framework/fields.py", line 524, in run_validation
    self.run_validators(value)
  File "/Users/alfred.fan/git/new/cmdb/env/lib/python3.6/site-packages/rest_framework/fields.py", line 538, in run_validators
    validator(value)
  File "/Users/alfred.fan/git/new/cmdb/env/lib/python3.6/site-packages/rest_framework/validators.py", line 81, in __call__
    if qs_exists(queryset):
  File "/Users/alfred.fan/git/new/cmdb/env/lib/python3.6/site-packages/rest_framework/validators.py", line 24, in qs_exists
    return queryset.exists()
  File "/Users/alfred.fan/git/new/cmdb/env/lib/python3.6/site-packages/django/db/models/query.py", line 718, in exists
    return self.query.has_results(using=self.db)
  File "/Users/alfred.fan/git/new/cmdb/env/lib/python3.6/site-packages/django/db/models/sql/query.py", line 516, in has_results
    return compiler.has_results()
  File "/Users/alfred.fan/git/new/cmdb/env/lib/python3.6/site-packages/django/db/models/sql/compiler.py", line 1035, in has_results
    return bool(self.execute_sql(SINGLE))
  File "/Users/alfred.fan/git/new/cmdb/env/lib/python3.6/site-packages/django/db/models/sql/compiler.py", line 1065, in execute_sql
    cursor.execute(sql, params)
  File "/Users/alfred.fan/git/new/cmdb/env/lib/python3.6/site-packages/django/db/backends/utils.py", line 100, in execute
    return super().execute(sql, params)
  File "/Users/alfred.fan/git/new/cmdb/env/lib/python3.6/site-packages/django/db/backends/utils.py", line 68, in execute
    return self._execute_with_wrappers(sql, params, many=False, executor=self._execute)
  File "/Users/alfred.fan/git/new/cmdb/env/lib/python3.6/site-packages/django/db/backends/utils.py", line 77, in _execute_with_wrappers
    return executor(sql, params, many, context)
  File "/Users/alfred.fan/git/new/cmdb/env/lib/python3.6/site-packages/django/db/backends/utils.py", line 85, in _execute
    return self.cursor.execute(sql, params)
  File "/Users/alfred.fan/git/new/cmdb/env/lib/python3.6/site-packages/django/db/utils.py", line 89, in __exit__
    raise dj_exc_value.with_traceback(traceback) from exc_value
  File "/Users/alfred.fan/git/new/cmdb/env/lib/python3.6/site-packages/django/db/backends/utils.py", line 85, in _execute
    return self.cursor.execute(sql, params)
  File "/Users/alfred.fan/git/new/cmdb/env/lib/python3.6/site-packages/django/db/backends/sqlite3/base.py", line 296, in execute
    return Database.Cursor.execute(self, query, params)
django.db.utils.OperationalError: no such table: cmdb_application
[03/Oct/2018 07:34:57] "POST /applications/ HTTP/1.1" 500 17741
Internal Server Error: /applications/
Traceback (most recent call last):
  File "/Users/alfred.fan/git/new/cmdb/env/lib/python3.6/site-packages/django/db/backends/utils.py", line 85, in _execute
    return self.cursor.execute(sql, params)
  File "/Users/alfred.fan/git/new/cmdb/env/lib/python3.6/site-packages/django/db/backends/sqlite3/base.py", line 296, in execute
    return Database.Cursor.execute(self, query, params)
sqlite3.OperationalError: no such table: cmdb_application

The above exception was the direct cause of the following exception:

Traceback (most recent call last):
  File "/Users/alfred.fan/git/new/cmdb/env/lib/python3.6/site-packages/django/core/handlers/exception.py", line 34, in inner
    response = get_response(request)
  File "/Users/alfred.fan/git/new/cmdb/env/lib/python3.6/site-packages/django/core/handlers/base.py", line 126, in _get_response
    response = self.process_exception_by_middleware(e, request)
  File "/Users/alfred.fan/git/new/cmdb/env/lib/python3.6/site-packages/django/core/handlers/base.py", line 124, in _get_response
    response = wrapped_callback(request, *callback_args, **callback_kwargs)
  File "/Users/alfred.fan/git/new/cmdb/env/lib/python3.6/site-packages/django/views/decorators/csrf.py", line 54, in wrapped_view
    return view_func(*args, **kwargs)
  File "/Users/alfred.fan/git/new/cmdb/env/lib/python3.6/site-packages/rest_framework/viewsets.py", line 103, in view
    return self.dispatch(request, *args, **kwargs)
  File "/Users/alfred.fan/git/new/cmdb/env/lib/python3.6/site-packages/rest_framework/views.py", line 483, in dispatch
    response = self.handle_exception(exc)
  File "/Users/alfred.fan/git/new/cmdb/env/lib/python3.6/site-packages/rest_framework/views.py", line 443, in handle_exception
    self.raise_uncaught_exception(exc)
  File "/Users/alfred.fan/git/new/cmdb/env/lib/python3.6/site-packages/rest_framework/views.py", line 480, in dispatch
    response = handler(request, *args, **kwargs)
  File "/Users/alfred.fan/git/new/cmdb/env/lib/python3.6/site-packages/rest_framework/mixins.py", line 20, in create
    serializer.is_valid(raise_exception=True)
  File "/Users/alfred.fan/git/new/cmdb/env/lib/python3.6/site-packages/rest_framework/serializers.py", line 236, in is_valid
    self._validated_data = self.run_validation(self.initial_data)
  File "/Users/alfred.fan/git/new/cmdb/env/lib/python3.6/site-packages/rest_framework/serializers.py", line 434, in run_validation
    value = self.to_internal_value(data)
  File "/Users/alfred.fan/git/new/cmdb/env/lib/python3.6/site-packages/rest_framework/serializers.py", line 488, in to_internal_value
    validated_value = field.run_validation(primitive_value)
  File "/Users/alfred.fan/git/new/cmdb/env/lib/python3.6/site-packages/rest_framework/fields.py", line 776, in run_validation
    return super(CharField, self).run_validation(data)
  File "/Users/alfred.fan/git/new/cmdb/env/lib/python3.6/site-packages/rest_framework/fields.py", line 524, in run_validation
    self.run_validators(value)
  File "/Users/alfred.fan/git/new/cmdb/env/lib/python3.6/site-packages/rest_framework/fields.py", line 538, in run_validators
    validator(value)
  File "/Users/alfred.fan/git/new/cmdb/env/lib/python3.6/site-packages/rest_framework/validators.py", line 81, in __call__
    if qs_exists(queryset):
  File "/Users/alfred.fan/git/new/cmdb/env/lib/python3.6/site-packages/rest_framework/validators.py", line 24, in qs_exists
    return queryset.exists()
  File "/Users/alfred.fan/git/new/cmdb/env/lib/python3.6/site-packages/django/db/models/query.py", line 718, in exists
    return self.query.has_results(using=self.db)
  File "/Users/alfred.fan/git/new/cmdb/env/lib/python3.6/site-packages/django/db/models/sql/query.py", line 516, in has_results
    return compiler.has_results()
  File "/Users/alfred.fan/git/new/cmdb/env/lib/python3.6/site-packages/django/db/models/sql/compiler.py", line 1035, in has_results
    return bool(self.execute_sql(SINGLE))
  File "/Users/alfred.fan/git/new/cmdb/env/lib/python3.6/site-packages/django/db/models/sql/compiler.py", line 1065, in execute_sql
    cursor.execute(sql, params)
  File "/Users/alfred.fan/git/new/cmdb/env/lib/python3.6/site-packages/django/db/backends/utils.py", line 100, in execute
    return super().execute(sql, params)
  File "/Users/alfred.fan/git/new/cmdb/env/lib/python3.6/site-packages/django/db/backends/utils.py", line 68, in execute
    return self._execute_with_wrappers(sql, params, many=False, executor=self._execute)
  File "/Users/alfred.fan/git/new/cmdb/env/lib/python3.6/site-packages/django/db/backends/utils.py", line 77, in _execute_with_wrappers
    return executor(sql, params, many, context)
  File "/Users/alfred.fan/git/new/cmdb/env/lib/python3.6/site-packages/django/db/backends/utils.py", line 85, in _execute
    return self.cursor.execute(sql, params)
  File "/Users/alfred.fan/git/new/cmdb/env/lib/python3.6/site-packages/django/db/utils.py", line 89, in __exit__
    raise dj_exc_value.with_traceback(traceback) from exc_value
  File "/Users/alfred.fan/git/new/cmdb/env/lib/python3.6/site-packages/django/db/backends/utils.py", line 85, in _execute
    return self.cursor.execute(sql, params)
  File "/Users/alfred.fan/git/new/cmdb/env/lib/python3.6/site-packages/django/db/backends/sqlite3/base.py", line 296, in execute
    return Database.Cursor.execute(self, query, params)
django.db.utils.OperationalError: no such table: cmdb_application
[03/Oct/2018 07:34:57] "POST /applications/ HTTP/1.1" 500 17741
Internal Server Error: /applications/
Traceback (most recent call last):
  File "/Users/alfred.fan/git/new/cmdb/env/lib/python3.6/site-packages/django/db/backends/utils.py", line 85, in _execute
    return self.cursor.execute(sql, params)
  File "/Users/alfred.fan/git/new/cmdb/env/lib/python3.6/site-packages/django/db/backends/sqlite3/base.py", line 296, in execute
    return Database.Cursor.execute(self, query, params)
sqlite3.OperationalError: no such table: cmdb_application

The above exception was the direct cause of the following exception:

Traceback (most recent call last):
  File "/Users/alfred.fan/git/new/cmdb/env/lib/python3.6/site-packages/django/core/handlers/exception.py", line 34, in inner
    response = get_response(request)
  File "/Users/alfred.fan/git/new/cmdb/env/lib/python3.6/site-packages/django/core/handlers/base.py", line 126, in _get_response
    response = self.process_exception_by_middleware(e, request)
  File "/Users/alfred.fan/git/new/cmdb/env/lib/python3.6/site-packages/django/core/handlers/base.py", line 124, in _get_response
    response = wrapped_callback(request, *callback_args, **callback_kwargs)
  File "/Users/alfred.fan/git/new/cmdb/env/lib/python3.6/site-packages/django/views/decorators/csrf.py", line 54, in wrapped_view
    return view_func(*args, **kwargs)
  File "/Users/alfred.fan/git/new/cmdb/env/lib/python3.6/site-packages/rest_framework/viewsets.py", line 103, in view
    return self.dispatch(request, *args, **kwargs)
  File "/Users/alfred.fan/git/new/cmdb/env/lib/python3.6/site-packages/rest_framework/views.py", line 483, in dispatch
    response = self.handle_exception(exc)
  File "/Users/alfred.fan/git/new/cmdb/env/lib/python3.6/site-packages/rest_framework/views.py", line 443, in handle_exception
    self.raise_uncaught_exception(exc)
  File "/Users/alfred.fan/git/new/cmdb/env/lib/python3.6/site-packages/rest_framework/views.py", line 480, in dispatch
    response = handler(request, *args, **kwargs)
  File "/Users/alfred.fan/git/new/cmdb/env/lib/python3.6/site-packages/rest_framework/mixins.py", line 20, in create
    serializer.is_valid(raise_exception=True)
  File "/Users/alfred.fan/git/new/cmdb/env/lib/python3.6/site-packages/rest_framework/serializers.py", line 236, in is_valid
    self._validated_data = self.run_validation(self.initial_data)
  File "/Users/alfred.fan/git/new/cmdb/env/lib/python3.6/site-packages/rest_framework/serializers.py", line 434, in run_validation
    value = self.to_internal_value(data)
  File "/Users/alfred.fan/git/new/cmdb/env/lib/python3.6/site-packages/rest_framework/serializers.py", line 488, in to_internal_value
    validated_value = field.run_validation(primitive_value)
  File "/Users/alfred.fan/git/new/cmdb/env/lib/python3.6/site-packages/rest_framework/fields.py", line 776, in run_validation
    return super(CharField, self).run_validation(data)
  File "/Users/alfred.fan/git/new/cmdb/env/lib/python3.6/site-packages/rest_framework/fields.py", line 524, in run_validation
    self.run_validators(value)
  File "/Users/alfred.fan/git/new/cmdb/env/lib/python3.6/site-packages/rest_framework/fields.py", line 538, in run_validators
    validator(value)
  File "/Users/alfred.fan/git/new/cmdb/env/lib/python3.6/site-packages/rest_framework/validators.py", line 81, in __call__
    if qs_exists(queryset):
  File "/Users/alfred.fan/git/new/cmdb/env/lib/python3.6/site-packages/rest_framework/validators.py", line 24, in qs_exists
    return queryset.exists()
  File "/Users/alfred.fan/git/new/cmdb/env/lib/python3.6/site-packages/django/db/models/query.py", line 718, in exists
    return self.query.has_results(using=self.db)
  File "/Users/alfred.fan/git/new/cmdb/env/lib/python3.6/site-packages/django/db/models/sql/query.py", line 516, in has_results
    return compiler.has_results()
  File "/Users/alfred.fan/git/new/cmdb/env/lib/python3.6/site-packages/django/db/models/sql/compiler.py", line 1035, in has_results
    return bool(self.execute_sql(SINGLE))
  File "/Users/alfred.fan/git/new/cmdb/env/lib/python3.6/site-packages/django/db/models/sql/compiler.py", line 1065, in execute_sql
    cursor.execute(sql, params)
  File "/Users/alfred.fan/git/new/cmdb/env/lib/python3.6/site-packages/django/db/backends/utils.py", line 100, in execute
    return super().execute(sql, params)
  File "/Users/alfred.fan/git/new/cmdb/env/lib/python3.6/site-packages/django/db/backends/utils.py", line 68, in execute
    return self._execute_with_wrappers(sql, params, many=False, executor=self._execute)
  File "/Users/alfred.fan/git/new/cmdb/env/lib/python3.6/site-packages/django/db/backends/utils.py", line 77, in _execute_with_wrappers
    return executor(sql, params, many, context)
  File "/Users/alfred.fan/git/new/cmdb/env/lib/python3.6/site-packages/django/db/backends/utils.py", line 85, in _execute
    return self.cursor.execute(sql, params)
  File "/Users/alfred.fan/git/new/cmdb/env/lib/python3.6/site-packages/django/db/utils.py", line 89, in __exit__
    raise dj_exc_value.with_traceback(traceback) from exc_value
  File "/Users/alfred.fan/git/new/cmdb/env/lib/python3.6/site-packages/django/db/backends/utils.py", line 85, in _execute
    return self.cursor.execute(sql, params)
  File "/Users/alfred.fan/git/new/cmdb/env/lib/python3.6/site-packages/django/db/backends/sqlite3/base.py", line 296, in execute
    return Database.Cursor.execute(self, query, params)
django.db.utils.OperationalError: no such table: cmdb_application
[03/Oct/2018 07:34:57] "POST /applications/ HTTP/1.1" 500 17741
Internal Server Error: /products/
Traceback (most recent call last):
  File "/Users/alfred.fan/git/new/cmdb/env/lib/python3.6/site-packages/django/db/backends/utils.py", line 85, in _execute
    return self.cursor.execute(sql, params)
  File "/Users/alfred.fan/git/new/cmdb/env/lib/python3.6/site-packages/django/db/backends/sqlite3/base.py", line 296, in execute
    return Database.Cursor.execute(self, query, params)
sqlite3.OperationalError: no such table: cmdb_product

The above exception was the direct cause of the following exception:

Traceback (most recent call last):
  File "/Users/alfred.fan/git/new/cmdb/env/lib/python3.6/site-packages/django/core/handlers/exception.py", line 34, in inner
    response = get_response(request)
  File "/Users/alfred.fan/git/new/cmdb/env/lib/python3.6/site-packages/django/core/handlers/base.py", line 126, in _get_response
    response = self.process_exception_by_middleware(e, request)
  File "/Users/alfred.fan/git/new/cmdb/env/lib/python3.6/site-packages/django/core/handlers/base.py", line 124, in _get_response
    response = wrapped_callback(request, *callback_args, **callback_kwargs)
  File "/Users/alfred.fan/git/new/cmdb/env/lib/python3.6/site-packages/django/views/decorators/csrf.py", line 54, in wrapped_view
    return view_func(*args, **kwargs)
  File "/Users/alfred.fan/git/new/cmdb/env/lib/python3.6/site-packages/rest_framework/viewsets.py", line 103, in view
    return self.dispatch(request, *args, **kwargs)
  File "/Users/alfred.fan/git/new/cmdb/env/lib/python3.6/site-packages/rest_framework/views.py", line 483, in dispatch
    response = self.handle_exception(exc)
  File "/Users/alfred.fan/git/new/cmdb/env/lib/python3.6/site-packages/rest_framework/views.py", line 443, in handle_exception
    self.raise_uncaught_exception(exc)
  File "/Users/alfred.fan/git/new/cmdb/env/lib/python3.6/site-packages/rest_framework/views.py", line 480, in dispatch
    response = handler(request, *args, **kwargs)
  File "/Users/alfred.fan/git/new/cmdb/env/lib/python3.6/site-packages/rest_framework/mixins.py", line 20, in create
    serializer.is_valid(raise_exception=True)
  File "/Users/alfred.fan/git/new/cmdb/env/lib/python3.6/site-packages/rest_framework/serializers.py", line 236, in is_valid
    self._validated_data = self.run_validation(self.initial_data)
  File "/Users/alfred.fan/git/new/cmdb/env/lib/python3.6/site-packages/rest_framework/serializers.py", line 434, in run_validation
    value = self.to_internal_value(data)
  File "/Users/alfred.fan/git/new/cmdb/env/lib/python3.6/site-packages/rest_framework/serializers.py", line 488, in to_internal_value
    validated_value = field.run_validation(primitive_value)
  File "/Users/alfred.fan/git/new/cmdb/env/lib/python3.6/site-packages/rest_framework/fields.py", line 776, in run_validation
    return super(CharField, self).run_validation(data)
  File "/Users/alfred.fan/git/new/cmdb/env/lib/python3.6/site-packages/rest_framework/fields.py", line 524, in run_validation
    self.run_validators(value)
  File "/Users/alfred.fan/git/new/cmdb/env/lib/python3.6/site-packages/rest_framework/fields.py", line 538, in run_validators
    validator(value)
  File "/Users/alfred.fan/git/new/cmdb/env/lib/python3.6/site-packages/rest_framework/validators.py", line 81, in __call__
    if qs_exists(queryset):
  File "/Users/alfred.fan/git/new/cmdb/env/lib/python3.6/site-packages/rest_framework/validators.py", line 24, in qs_exists
    return queryset.exists()
  File "/Users/alfred.fan/git/new/cmdb/env/lib/python3.6/site-packages/django/db/models/query.py", line 718, in exists
    return self.query.has_results(using=self.db)
  File "/Users/alfred.fan/git/new/cmdb/env/lib/python3.6/site-packages/django/db/models/sql/query.py", line 516, in has_results
    return compiler.has_results()
  File "/Users/alfred.fan/git/new/cmdb/env/lib/python3.6/site-packages/django/db/models/sql/compiler.py", line 1035, in has_results
    return bool(self.execute_sql(SINGLE))
  File "/Users/alfred.fan/git/new/cmdb/env/lib/python3.6/site-packages/django/db/models/sql/compiler.py", line 1065, in execute_sql
    cursor.execute(sql, params)
  File "/Users/alfred.fan/git/new/cmdb/env/lib/python3.6/site-packages/django/db/backends/utils.py", line 100, in execute
    return super().execute(sql, params)
  File "/Users/alfred.fan/git/new/cmdb/env/lib/python3.6/site-packages/django/db/backends/utils.py", line 68, in execute
    return self._execute_with_wrappers(sql, params, many=False, executor=self._execute)
  File "/Users/alfred.fan/git/new/cmdb/env/lib/python3.6/site-packages/django/db/backends/utils.py", line 77, in _execute_with_wrappers
    return executor(sql, params, many, context)
  File "/Users/alfred.fan/git/new/cmdb/env/lib/python3.6/site-packages/django/db/backends/utils.py", line 85, in _execute
    return self.cursor.execute(sql, params)
  File "/Users/alfred.fan/git/new/cmdb/env/lib/python3.6/site-packages/django/db/utils.py", line 89, in __exit__
    raise dj_exc_value.with_traceback(traceback) from exc_value
  File "/Users/alfred.fan/git/new/cmdb/env/lib/python3.6/site-packages/django/db/backends/utils.py", line 85, in _execute
    return self.cursor.execute(sql, params)
  File "/Users/alfred.fan/git/new/cmdb/env/lib/python3.6/site-packages/django/db/backends/sqlite3/base.py", line 296, in execute
    return Database.Cursor.execute(self, query, params)
django.db.utils.OperationalError: no such table: cmdb_product
[03/Oct/2018 07:35:59] "POST /products/ HTTP/1.1" 500 17713
